<sdf version='1.7'>
  <world name='default'>
    <light name='sun' type='directional'>
      <cast_shadows>1</cast_shadows>
      <pose>0 0 10 0 -0 0</pose>
      <diffuse>0.8 0.8 0.8 1</diffuse>
      <specular>0.2 0.2 0.2 1</specular>
      <attenuation>
        <range>1000</range>
        <constant>0.9</constant>
        <linear>0.01</linear>
        <quadratic>0.001</quadratic>
      </attenuation>
      <direction>-0.5 0.1 -0.9</direction>
      <spot>
        <inner_angle>0</inner_angle>
        <outer_angle>0</outer_angle>
        <falloff>0</falloff>
      </spot>
    </light>
    <model name='ground_plane'>
      <static>1</static>
      <link name='link'>
        <collision name='collision'>
          <geometry>
            <plane>
              <normal>0 0 1</normal>
              <size>100 100</size>
            </plane>
          </geometry>
          <surface>
            <contact>
              <collide_bitmask>65535</collide_bitmask>
              <ode/>
            </contact>
            <friction>
              <ode>
                <mu>100</mu>
                <mu2>50</mu2>
              </ode>
              <torsional>
                <ode/>
              </torsional>
            </friction>
            <bounce/>
          </surface>
          <max_contacts>10</max_contacts>
        </collision>
        <visual name='visual'>
          <cast_shadows>0</cast_shadows>
          <geometry>
            <plane>
              <normal>0 0 1</normal>
              <size>100 100</size>
            </plane>
          </geometry>
          <material>
            <script>
              <uri>file://media/materials/scripts/gazebo.material</uri>
              <name>Gazebo/Grey</name>
            </script>
          </material>
        </visual>
        <self_collide>0</self_collide>
        <enable_wind>0</enable_wind>
        <kinematic>0</kinematic>
      </link>
    </model>
    <gravity>0 0 -9.8</gravity>
    <magnetic_field>6e-06 2.3e-05 -4.2e-05</magnetic_field>
    <atmosphere type='adiabatic'/>
    <physics type='ode'>
      <max_step_size>0.001</max_step_size>
      <real_time_factor>1</real_time_factor>
      <real_time_update_rate>1000</real_time_update_rate>
    </physics>
    <scene>
      <ambient>0.4 0.4 0.4 1</ambient>
      <background>0.7 0.7 0.7 1</background>
      <shadows>1</shadows>
    </scene>
    <wind/>
    <spherical_coordinates>
      <surface_model>EARTH_WGS84</surface_model>
      <latitude_deg>0</latitude_deg>
      <longitude_deg>0</longitude_deg>
      <elevation>0</elevation>
      <heading_deg>0</heading_deg>
    </spherical_coordinates>
    <model name='kitchen'>
      <static>1</static>
      <link name='kitchen'>
        <visual name='visual'>
          <geometry>
            <mesh>
              <uri>model://Kitchen/meshes/model.dae</uri>
              <scale>0.5 0.5 0.5</scale>
            </mesh>
          </geometry>
        </visual>
        <self_collide>0</self_collide>
        <enable_wind>0</enable_wind>
        <kinematic>0</kinematic>
      </link>
      <pose>-0.804049 0.532603 0 0 -0 0</pose>
    </model>
    <model name='kitchen_box'>
      <link name='link_0'>
        <pose>-4.0678 1.99751 0.272777 0 -0 0</pose>
        <visual name='visual'>
          <pose>0 0 0 0 -0 0</pose>
          <geometry>
            <box>
              <size>0.331403 1 0.5</size>
            </box>
          </geometry>
          <material>
            <lighting>1</lighting>
            <script>
              <uri>file://media/materials/scripts/gazebo.material</uri>
              <name>Gazebo/Grey</name>
            </script>
            <shader type='pixel'/>
          </material>
          <transparency>0</transparency>
          <cast_shadows>1</cast_shadows>
        </visual>
        <collision name='collision'>
          <laser_retro>0</laser_retro>
          <max_contacts>10</max_contacts>
          <pose>0 0 0 0 -0 0</pose>
          <geometry>
            <box>
              <size>0.331403 1 0.5</size>
            </box>
          </geometry>
          <surface>
            <friction>
              <ode>
                <mu>1</mu>
                <mu2>1</mu2>
                <fdir1>0 0 0</fdir1>
                <slip1>0</slip1>
                <slip2>0</slip2>
              </ode>
              <torsional>
                <coefficient>1</coefficient>
                <patch_radius>0</patch_radius>
                <surface_radius>0</surface_radius>
                <use_patch_radius>1</use_patch_radius>
                <ode>
                  <slip>0</slip>
                </ode>
              </torsional>
            </friction>
            <bounce>
              <restitution_coefficient>0</restitution_coefficient>
              <threshold>1e+06</threshold>
            </bounce>
            <contact>
              <collide_without_contact>0</collide_without_contact>
              <collide_without_contact_bitmask>1</collide_without_contact_bitmask>
              <collide_bitmask>1</collide_bitmask>
              <ode>
                <soft_cfm>0</soft_cfm>
                <soft_erp>0.2</soft_erp>
                <kp>1e+13</kp>
                <kd>1</kd>
                <max_vel>0.01</max_vel>
                <min_depth>0</min_depth>
              </ode>
              <bullet>
                <split_impulse>1</split_impulse>
                <split_impulse_penetration_threshold>-0.01</split_impulse_penetration_threshold>
                <soft_cfm>0</soft_cfm>
                <soft_erp>0.2</soft_erp>
                <kp>1e+13</kp>
                <kd>1</kd>
              </bullet>
            </contact>
          </surface>
        </collision>
        <self_collide>0</self_collide>
        <enable_wind>0</enable_wind>
        <kinematic>0</kinematic>
        <inertial>
          <pose>0 0 0 0 -0 0</pose>
          <inertia>
            <ixx>1</ixx>
            <ixy>0</ixy>
            <ixz>0</ixz>
            <iyy>1</iyy>
            <iyz>0</iyz>
            <izz>1</izz>
          </inertia>
          <mass>1</mass>
        </inertial>
      </link>
      <link name='link_0_clone'>
        <pose>-3.72184 2.32096 0.272777 0 0 -1.57838</pose>
        <visual name='visual'>
          <pose>0 0 0 0 -0 0</pose>
          <geometry>
            <box>
              <size>0.331403 1 0.5</size>
            </box>
          </geometry>
          <material>
            <lighting>1</lighting>
            <script>
              <uri>file://media/materials/scripts/gazebo.material</uri>
              <name>Gazebo/Grey</name>
            </script>
            <shader type='pixel'/>
          </material>
          <transparency>0</transparency>
          <cast_shadows>1</cast_shadows>
        </visual>
        <collision name='collision'>
          <laser_retro>0</laser_retro>
          <max_contacts>10</max_contacts>
          <pose>0 0 0 0 -0 0</pose>
          <geometry>
            <box>
              <size>0.331403 1 0.5</size>
            </box>
          </geometry>
          <surface>
            <friction>
              <ode>
                <mu>1</mu>
                <mu2>1</mu2>
                <fdir1>0 0 0</fdir1>
                <slip1>0</slip1>
                <slip2>0</slip2>
              </ode>
              <torsional>
                <coefficient>1</coefficient>
                <patch_radius>0</patch_radius>
                <surface_radius>0</surface_radius>
                <use_patch_radius>1</use_patch_radius>
                <ode>
                  <slip>0</slip>
                </ode>
              </torsional>
            </friction>
            <bounce>
              <restitution_coefficient>0</restitution_coefficient>
              <threshold>1e+06</threshold>
            </bounce>
            <contact>
              <collide_without_contact>0</collide_without_contact>
              <collide_without_contact_bitmask>1</collide_without_contact_bitmask>
              <collide_bitmask>1</collide_bitmask>
              <ode>
                <soft_cfm>0</soft_cfm>
                <soft_erp>0.2</soft_erp>
                <kp>1e+13</kp>
                <kd>1</kd>
                <max_vel>0.01</max_vel>
                <min_depth>0</min_depth>
              </ode>
              <bullet>
                <split_impulse>1</split_impulse>
                <split_impulse_penetration_threshold>-0.01</split_impulse_penetration_threshold>
                <soft_cfm>0</soft_cfm>
                <soft_erp>0.2</soft_erp>
                <kp>1e+13</kp>
                <kd>1</kd>
              </bullet>
            </contact>
          </surface>
        </collision>
        <self_collide>0</self_collide>
        <enable_wind>0</enable_wind>
        <kinematic>0</kinematic>
        <inertial>
          <pose>0 0 0 0 -0 0</pose>
          <inertia>
            <ixx>1</ixx>
            <ixy>0</ixy>
            <ixz>0</ixz>
            <iyy>1</iyy>
            <iyz>0</iyz>
            <izz>1</izz>
          </inertia>
          <mass>1</mass>
        </inertial>
      </link>
      <static>0</static>
      <allow_auto_disable>1</allow_auto_disable>
      <pose>5.3022 -2.11888 0 0 -0 0</pose>
    </model>
    <model name='wood_cube_2_5cm'>
      <link name='link'>
        <pose>0 0 0.0125 0 -0 0</pose>
        <inertial>
          <mass>0.0073</mass>
          <inertia>
            <ixx>7.60417e-07</ixx>
            <ixy>0</ixy>
            <ixz>0</ixz>
            <iyy>7.60417e-07</iyy>
            <iyz>0</iyz>
            <izz>7.60417e-07</izz>
          </inertia>
          <pose>0 0 0 0 -0 0</pose>
        </inertial>
        <collision name='collision'>
          <geometry>
            <box>
              <size>0.025 0.025 0.025</size>
            </box>
          </geometry>
          <surface>
            <contact>
              <poissons_ratio>0.347</poissons_ratio>
              <elastic_modulus>8.8e+09</elastic_modulus>
              <ode>
                <kp>100000</kp>
                <kd>100</kd>
                <max_vel>100</max_vel>
                <min_depth>0.001</min_depth>
              </ode>
            </contact>
            <friction>
              <torsional>
                <coefficient>1</coefficient>
                <use_patch_radius>0</use_patch_radius>
                <surface_radius>0.01</surface_radius>
                <ode/>
              </torsional>
              <ode/>
            </friction>
            <bounce/>
          </surface>
          <max_contacts>10</max_contacts>
        </collision>
        <visual name='visual'>
          <geometry>
            <box>
              <size>0.025 0.025 0.025</size>
            </box>
          </geometry>
          <material>
            <script>
              <uri>file://media/materials/scripts/gazebo.material</uri>
              <name>Gazebo/Wood</name>
            </script>
          </material>
        </visual>
        <self_collide>0</self_collide>
        <enable_wind>0</enable_wind>
        <kinematic>0</kinematic>
      </link>
      <pose>0.431836 -1.58687 0 0 -0 0</pose>
    </model>
    <state world_name='default'>
      <sim_time>1245 402000000</sim_time>
      <real_time>50 327129937</real_time>
      <wall_time>1646504710 375393388</wall_time>
      <iterations>49623</iterations>
      <model name='bowl'>
        <pose>0.083951 -0.264698 0.517455 8e-06 -8e-06 0.000284</pose>
        <scale>1 1 1</scale>
        <link name='bowl'>
          <pose>0.083951 -0.264698 0.517455 8e-06 -8e-06 0.000284</pose>
          <velocity>0 0 0 0 -0 0</velocity>
          <acceleration>0 0 -9.8 0 -0 0</acceleration>
          <wrench>0 0 -9.8 0 -0 0</wrench>
        </link>
      </model>
      <model name='ground_plane'>
        <pose>0 0 0 0 -0 0</pose>
        <scale>1 1 1</scale>
        <link name='link'>
          <pose>0 0 0 0 -0 0</pose>
          <velocity>0 0 0 0 -0 0</velocity>
          <acceleration>0 0 0 0 -0 0</acceleration>
          <wrench>0 0 0 0 -0 0</wrench>
        </link>
      </model>
      <model name='kitchen'>
        <pose>0.465896 1.57043 0 0 0 -3.13984</pose>
        <scale>1 1 1</scale>
        <link name='kitchen'>
          <pose>0.465896 1.57043 0 0 0 -3.13984</pose>
          <velocity>0 0 0 0 -0 0</velocity>
          <acceleration>0 0 0 0 -0 0</acceleration>
          <wrench>0 0 0 0 -0 0</wrench>
        </link>
      </model>
      <model name='kitchen_box'>
        <pose>-3.80086 2.15124 -0.022799 -8e-06 3e-06 3.13895</pose>
        <scale>1 1 1</scale>
        <link name='link_0'>
          <pose>0.261637 0.142968 0.249973 -8e-06 3e-06 3.13895</pose>
          <velocity>0 0 0 0 -0 0</velocity>
          <acceleration>0.072566 0.199388 -14.473 1.56104 -0.579631 0.002304</acceleration>
          <wrench>0.072566 0.199388 -14.473 0 -0 0</wrench>
        </link>
        <link name='link_0_clone'>
          <pose>-0.072627 -0.26017 0.249585 3e-05 -2.4e-05 1.57683</pose>
          <velocity>0 0 0 0 -0 0</velocity>
          <acceleration>-0.427678 -0.600241 -22.9476 1.70263 1.527 -0.141677</acceleration>
          <wrench>-0.427678 -0.600241 -22.9476 0 -0 0</wrench>
        </link>
      </model>
      <model name='robot'>
        <pose>-0 0 -0 0 -0 0</pose>
        <scale>1 1 1</scale>
        <link name='base_link'>
          <pose>-0 0 0.5 -1e-06 -4e-06 0</pose>
          <velocity>-0 -0 -0 2.8e-05 -1.4e-05 -1.5e-05</velocity>
          <acceleration>-4e-06 -8e-06 -8e-06 0.112451 -0.023072 -0.036649</acceleration>
          <wrench>-4.1e-05 -7.5e-05 -7.6e-05 0 -0 0</wrench>
        </link>
        <link name='gripper_link_1'>
          <pose>0.08418 -0.028587 0.744686 1.5571 -0.000114 1.57083</pose>
          <velocity>0.00091 0.000288 -0.000297 0.01073 0.010619 0.001328</velocity>
          <acceleration>0.092485 -2.30817 0.470405 -0.128547 -1.21363 1.97431</acceleration>
          <wrench>0.000891 -0.022243 0.004533 0 -0 0</wrench>
        </link>
        <link name='gripper_link_2'>
          <pose>0.084193 -0.001586 0.744739 1.55539 -7.3e-05 1.57081</pose>
          <velocity>0.000872 0.000263 -0.000344 -0.006606 0.010767 0.001331</velocity>
          <acceleration>0.008354 1.39529 0.151036 2.09747 0.356767 -3.04012</acceleration>
          <wrench>8.1e-05 0.013446 0.001455 0 -0 0</wrench>
        </link>
        <link name='link_1'>
          <pose>0 -0 0.556 0 3e-06 -4e-06</pose>
          <velocity>-0 5e-06 -2e-06 -3.1e-05 8e-06 4.1e-05</velocity>
          <acceleration>-0.000509 0.01897 -0.008618 -0.124577 0.021648 -0.054581</acceleration>
          <wrench>-3.5e-05 0.001291 -0.000586 0 -0 0</wrench>
        </link>
        <link name='link_2'>
          <pose>0.01392 -0 0.596276 1.57081 -0.432489 -5e-06</pose>
          <velocity>7e-06 1e-05 2e-06 0.000285 0.004047 -6.5e-05</velocity>
          <acceleration>0.013031 0.021563 0.001929 2.29496 -0.008454 1.84652</acceleration>
          <wrench>0.000839 0.001388 0.000124 0 -0 0</wrench>
        </link>
        <link name='link_3'>
          <pose>-0.036375 -1e-06 0.705227 1.5708 -0.013571 -9e-06</pose>
          <velocity>0.000447 -5e-06 0.000207 0.000269 0.004918 0.001168</velocity>
          <acceleration>-0.015255 0.149787 0.03005 0.495839 0.07148 2.75568</acceleration>
          <wrench>-0.000767 0.00753 0.001511 0 -0 0</wrench>
        </link>
        <link name='link_4'>
          <pose>0.053408 0.011498 0.701343 1.57082 -1.3e-05 1.56949</pose>
          <velocity>0.000419 0.00014 -0.000211 8.2e-05 0.004597 0.001079</velocity>
          <acceleration>0.001376 0.388812 0.064314 1.47095 -0.314336 1.73497</acceleration>
          <wrench>2.3e-05 0.006415 0.001061 0 -0 0</wrench>
        </link>
        <link name='link_5'>
          <pose>0.081367 0.003487 0.706708 1.57275 -0.013613 2.7e-05</pose>
          <velocity>0.000455 0.000189 -0.000325 -0.001683 0.010732 0.001454</velocity>
          <acceleration>0.065685 0.446717 0.084496 -1.46264 -0.0893 2.15644</acceleration>
          <wrench>0.001033 0.007023 0.001328 0 -0 0</wrench>
        </link>
        <link name='mums_assistant_pedestal_link'>
          <pose>-0 0 -0 0 -0 0</pose>
          <velocity>-0 -0 0 0 -0 0</velocity>
          <acceleration>0 0 -0 -0 -0 -0</acceleration>
          <wrench>0 0 -0 0 -0 0</wrench>
        </link>
      </model>
      <model name='wood_cube_2_5cm'>
        <pose>0.164844 0.115512 0.499972 -5e-06 -0 -0.018249</pose>
        <scale>1 1 1</scale>
        <link name='link'>
          <pose>0.164844 0.115512 0.512472 -5e-06 -0 -0.018249</pose>
          <velocity>0 0 0 0 -0 0</velocity>
          <acceleration>0 0 -9.8 0 -0 0</acceleration>
          <wrench>0 0 -0.07154 0 -0 0</wrench>
        </link>
      </model>
      <light name='sun'>
        <pose>0 0 10 0 -0 0</pose>
      </light>
    </state>
    <gui fullscreen='0'>
      <camera name='user_camera'>
        <pose>-0.107985 -0.071541 5.57068 0 1.51779 -0.034741</pose>
        <view_controller>ortho</view_controller>
        <projection_type>orthographic</projection_type>
      </camera>
    </gui>
    <model name='robot'>
      <joint name='joint_0' type='fixed'>
        <pose relative_to='__model__'>0 0 0 0 -0 0</pose>
        <parent>world</parent>
        <child>mums_assistant_pedestal_link</child>
      </joint>
      <link name='mums_assistant_pedestal_link'>
        <pose relative_to='joint_0'>0 0 0 0 -0 0</pose>
        <inertial>
          <pose>0 0 0 0 -0 0</pose>
          <mass>500</mass>
          <inertia>
            <ixx>0.001</ixx>
            <ixy>0</ixy>
            <ixz>0</ixz>
            <iyy>0.001</iyy>
            <iyz>0</iyz>
            <izz>0.001</izz>
          </inertia>
        </inertial>
        <collision name='mums_assistant_pedestal_link_collision'>
          <pose>0 0 0.25 0 -0 0</pose>
          <geometry>
            <box>
              <size>0.15 0.15 0.5</size>
            </box>
          </geometry>
          <surface>
            <contact>
              <ode/>
            </contact>
            <friction>
              <ode/>
              <torsional>
                <ode/>
              </torsional>
            </friction>
            <bounce/>
          </surface>
          <max_contacts>10</max_contacts>
        </collision>
        <visual name='mums_assistant_pedestal_link_visual'>
          <pose>0 0 0.25 0 -0 0</pose>
          <geometry>
            <box>
              <size>0.15 0.15 0.5</size>
            </box>
          </geometry>
          <material>
            <script>
              <name>Gazebo/DarkGray</name>
              <uri>file://media/materials/scripts/gazebo.material</uri>
            </script>
          </material>
        </visual>
        <self_collide>0</self_collide>
        <enable_wind>0</enable_wind>
        <kinematic>0</kinematic>
      </link>
      <joint name='ma_to_pedestal' type='fixed'>
        <pose relative_to='__model__'>0 0 0.5 0 -0 0</pose>
        <parent>world</parent>
        <child>base_link</child>
      </joint>
      <link name='base_link'>
        <pose relative_to='ma_to_pedestal'>0 0 0 0 -0 0</pose>
        <inertial>
          <pose>0 0 0 0 -0 0</pose>
          <mass>10</mass>
          <inertia>
            <ixx>0.00013766</ixx>
            <ixy>-1.2679e-08</ixy>
            <ixz>-5.1003e-09</ixz>
            <iyy>0.00012799</iyy>
            <iyz>-3.914e-06</iyz>
            <izz>0.00020798</izz>
          </inertia>
        </inertial>
        <collision name='base_link_collision'>
          <pose>0 0 0 0 -0 0</pose>
          <geometry>
            <mesh>
              <scale>1 1 1</scale>
              <uri>/home/mrinal/ros_ws/catkin_ws/src/mums_assistant/meshes/base_link.STL</uri>
            </mesh>
          </geometry>
          <max_contacts>10</max_contacts>
          <surface>
            <contact>
              <ode/>
            </contact>
            <bounce/>
            <friction>
              <torsional>
                <ode/>
              </torsional>
              <ode/>
            </friction>
          </surface>
        </collision>
        <visual name='base_link_visual'>
          <pose>0 0 0 0 -0 0</pose>
          <geometry>
            <mesh>
              <scale>1 1 1</scale>
              <uri>/home/mrinal/ros_ws/catkin_ws/src/mums_assistant/meshes/base_link.STL</uri>
            </mesh>
          </geometry>
        </visual>
        <self_collide>0</self_collide>
        <enable_wind>0</enable_wind>
        <kinematic>0</kinematic>
      </link>
      <joint name='joint_1' type='revolute'>
        <pose relative_to='base_link'>0 0 0.056 0 -0 0</pose>
        <parent>base_link</parent>
        <child>link_1</child>
        <axis>
          <xyz>0 0 1</xyz>
          <limit>
            <lower>-1.57</lower>
            <upper>1.57</upper>
            <effort>0.92</effort>
            <velocity>6.16</velocity>
          </limit>
          <dynamics>
            <damping>0</damping>
            <friction>0</friction>
            <spring_reference>0</spring_reference>
            <spring_stiffness>0</spring_stiffness>
          </dynamics>
        </axis>
      </joint>
      <link name='link_1'>
        <pose relative_to='joint_1'>0 0 0 0 -0 0</pose>
        <inertial>
          <pose>0.001372 0.006435 0.017289 0 -0 0</pose>
          <mass>0.068038</mass>
          <inertia>
            <ixx>4.5018e-05</ixx>
            <ixy>-6.4176e-07</ixy>
            <ixz>-6.2428e-06</ixz>
            <iyy>5.8133e-05</iyy>
            <iyz>-5.1777e-06</iyz>
            <izz>5.4676e-05</izz>
          </inertia>
        </inertial>
        <collision name='link_1_collision'>
          <pose>0 0 0 0 -0 0</pose>
          <geometry>
            <mesh>
              <scale>1 1 1</scale>
              <uri>/home/mrinal/ros_ws/catkin_ws/src/mums_assistant/meshes/link_1.STL</uri>
            </mesh>
          </geometry>
          <surface>
            <contact>
              <ode/>
            </contact>
            <friction>
              <ode/>
              <torsional>
                <ode/>
              </torsional>
            </friction>
            <bounce/>
          </surface>
          <max_contacts>10</max_contacts>
        </collision>
        <visual name='link_1_visual'>
          <pose>0 0 0 0 -0 0</pose>
          <geometry>
            <mesh>
              <scale>1 1 1</scale>
              <uri>/home/mrinal/ros_ws/catkin_ws/src/mums_assistant/meshes/link_1.STL</uri>
            </mesh>
          </geometry>
        </visual>
        <self_collide>1</self_collide>
        <enable_wind>0</enable_wind>
        <kinematic>0</kinematic>
      </link>
      <joint name='joint_2' type='revolute'>
        <pose relative_to='link_1'>0.013919 0 0.040276 1.5708 -0.4325 0</pose>
        <parent>link_1</parent>
        <child>link_2</child>
        <axis>
          <xyz>0 0 1</xyz>
          <limit>
            <lower>-1.57</lower>
            <upper>1.57</upper>
            <effort>0.92</effort>
            <velocity>6.16</velocity>
          </limit>
          <dynamics>
            <damping>0</damping>
            <friction>0</friction>
            <spring_reference>0</spring_reference>
            <spring_stiffness>0</spring_stiffness>
          </dynamics>
        </axis>
      </joint>
      <link name='link_2'>
        <pose relative_to='joint_2'>0 0 0 0 -0 0</pose>
        <inertial>
          <pose>-0.00013 0.05859 0.003769 0 -0 0</pose>
          <mass>0.064392</mass>
          <inertia>
            <ixx>0.00010704</ixx>
            <ixy>-1.6405e-09</ixy>
            <ixz>2.3498e-10</ixz>
            <iyy>9.11e-06</iyy>
            <iyz>2.3961e-07</iyz>
            <izz>0.00011184</izz>
          </inertia>
        </inertial>
        <collision name='link_2_collision'>
          <pose>0 0 0 0 -0 0</pose>
          <geometry>
            <mesh>
              <scale>1 1 1</scale>
              <uri>/home/mrinal/ros_ws/catkin_ws/src/mums_assistant/meshes/link_2.STL</uri>
            </mesh>
          </geometry>
          <surface>
            <contact>
              <ode/>
            </contact>
            <friction>
              <ode/>
              <torsional>
                <ode/>
              </torsional>
            </friction>
            <bounce/>
          </surface>
          <max_contacts>10</max_contacts>
        </collision>
        <visual name='link_2_visual'>
          <pose>0 0 0 0 -0 0</pose>
          <geometry>
            <mesh>
              <scale>1 1 1</scale>
              <uri>/home/mrinal/ros_ws/catkin_ws/src/mums_assistant/meshes/link_2.STL</uri>
            </mesh>
          </geometry>
        </visual>
        <self_collide>1</self_collide>
        <enable_wind>0</enable_wind>
        <kinematic>0</kinematic>
      </link>
      <joint name='joint_3' type='revolute'>
        <pose relative_to='link_2'>0 0.12 0 0 0 -0.41891</pose>
        <parent>link_2</parent>
        <child>link_3</child>
        <axis>
          <xyz>0 0 -1</xyz>
          <limit>
            <lower>-1.57</lower>
            <upper>1.57</upper>
            <effort>0.92</effort>
            <velocity>6.16</velocity>
          </limit>
          <dynamics>
            <damping>0</damping>
            <friction>0</friction>
            <spring_reference>0</spring_reference>
            <spring_stiffness>0</spring_stiffness>
          </dynamics>
        </axis>
      </joint>
      <link name='link_3'>
        <pose relative_to='joint_3'>0 0 0 0 -0 0</pose>
        <inertial>
          <pose>0.039285 2.8e-05 -0.011409 0 -0 0</pose>
          <mass>0.050268</mass>
          <inertia>
            <ixx>9.2868e-06</ixx>
            <ixy>-6.9582e-08</ixy>
            <ixz>2.8754e-07</ixz>
            <iyy>5.4601e-05</iyy>
            <iyz>5.3527e-11</iyz>
            <izz>5.8149e-05</izz>
          </inertia>
        </inertial>
        <collision name='link_3_collision'>
          <pose>0 0 0 0 -0 0</pose>
          <geometry>
            <mesh>
              <scale>1 1 1</scale>
              <uri>/home/mrinal/ros_ws/catkin_ws/src/mums_assistant/meshes/link_3.STL</uri>
            </mesh>
          </geometry>
          <surface>
            <contact>
              <ode/>
            </contact>
            <friction>
              <ode/>
              <torsional>
                <ode/>
              </torsional>
            </friction>
            <bounce/>
          </surface>
          <max_contacts>10</max_contacts>
        </collision>
        <visual name='link_3_visual'>
          <pose>0 0 0 0 -0 0</pose>
          <geometry>
            <mesh>
              <scale>1 1 1</scale>
              <uri>/home/mrinal/ros_ws/catkin_ws/src/mums_assistant/meshes/link_3.STL</uri>
            </mesh>
          </geometry>
        </visual>
        <self_collide>1</self_collide>
        <enable_wind>0</enable_wind>
        <kinematic>0</kinematic>
      </link>
      <joint name='joint_4' type='revolute'>
        <pose relative_to='link_3'>0.089722 -0.0051 -0.0115 0 1.5695 -0.013594</pose>
        <parent>link_3</parent>
        <child>link_4</child>
        <axis>
          <xyz>0.001304 0.013594 0.99991</xyz>
          <limit>
            <lower>-1.57</lower>
            <upper>1.57</upper>
            <effort>0.098</effort>
            <velocity>8.73</velocity>
          </limit>
          <dynamics>
            <damping>0</damping>
            <friction>0</friction>
            <spring_reference>0</spring_reference>
            <spring_stiffness>0</spring_stiffness>
          </dynamics>
        </axis>
      </joint>
      <link name='link_4'>
        <pose relative_to='joint_4'>0 0 0 0 -0 0</pose>
        <inertial>
          <pose>-0.005251 0.005279 0.017806 0 -0 0</pose>
          <mass>0.016499</mass>
          <inertia>
            <ixx>5.0238e-06</ixx>
            <ixy>5.8794e-09</ixy>
            <ixz>5.7259e-07</ixz>
            <iyy>3.9123e-06</iyy>
            <iyz>-5.0337e-09</iyz>
            <izz>2.6108e-06</izz>
          </inertia>
        </inertial>
        <collision name='link_4_collision'>
          <pose>0 0 0 0 -0 0</pose>
          <geometry>
            <mesh>
              <scale>1 1 1</scale>
              <uri>/home/mrinal/ros_ws/catkin_ws/src/mums_assistant/meshes/link_4.STL</uri>
            </mesh>
          </geometry>
          <surface>
            <contact>
              <ode/>
            </contact>
            <friction>
              <ode/>
              <torsional>
                <ode/>
              </torsional>
            </friction>
            <bounce/>
          </surface>
          <max_contacts>10</max_contacts>
        </collision>
        <visual name='link_4_visual'>
          <pose>0 0 0 0 -0 0</pose>
          <geometry>
            <mesh>
              <scale>1 1 1</scale>
              <uri>/home/mrinal/ros_ws/catkin_ws/src/mums_assistant/meshes/link_4.STL</uri>
            </mesh>
          </geometry>
        </visual>
        <self_collide>1</self_collide>
        <enable_wind>0</enable_wind>
        <kinematic>0</kinematic>
      </link>
      <joint name='joint_5' type='revolute'>
        <pose relative_to='link_4'>-0.007974 0.005366 0.027968 -1.4733 -1.5571 1.4752</pose>
        <parent>link_4</parent>
        <child>link_5</child>
        <axis>
          <xyz>0 0 1</xyz>
          <limit>
            <lower>-1.57</lower>
            <upper>1.57</upper>
            <effort>0.098</effort>
            <velocity>8.73</velocity>
          </limit>
          <dynamics>
            <damping>0</damping>
            <friction>0</friction>
            <spring_reference>0</spring_reference>
            <spring_stiffness>0</spring_stiffness>
          </dynamics>
        </axis>
      </joint>
      <link name='link_5'>
        <pose relative_to='joint_5'>0 0 0 0 -0 0</pose>
        <inertial>
          <pose>0.005815 0.023551 0.015976 0 -0 0</pose>
          <mass>0.015721</mass>
          <inertia>
            <ixx>8.1159e-06</ixx>
            <ixy>-1.3638e-06</ixy>
            <ixz>-3.5027e-07</ixz>
            <iyy>2.5603e-06</iyy>
            <iyz>-1.4286e-06</iyz>
            <izz>7.2474e-06</izz>
          </inertia>
        </inertial>
        <collision name='link_5_collision'>
          <pose>0 0 0 0 -0 0</pose>
          <geometry>
            <mesh>
              <scale>1 1 1</scale>
              <uri>/home/mrinal/ros_ws/catkin_ws/src/mums_assistant/meshes/link_5.STL</uri>
            </mesh>
          </geometry>
          <surface>
            <contact>
              <ode/>
            </contact>
            <friction>
              <ode/>
              <torsional>
                <ode/>
              </torsional>
            </friction>
            <bounce/>
          </surface>
          <max_contacts>10</max_contacts>
        </collision>
        <visual name='link_5_visual'>
          <pose>0 0 0 0 -0 0</pose>
          <geometry>
            <mesh>
              <scale>1 1 1</scale>
              <uri>/home/mrinal/ros_ws/catkin_ws/src/mums_assistant/meshes/link_5.STL</uri>
            </mesh>
          </geometry>
        </visual>
        <self_collide>1</self_collide>
        <enable_wind>0</enable_wind>
        <kinematic>0</kinematic>
      </link>
      <joint name='gripper_joint_1' type='revolute'>
        <pose relative_to='link_5'>0.003329 0.038 0.031999 -1.5708 1.569 -1.5707</pose>
        <parent>link_5</parent>
        <child>gripper_link_1</child>
        <axis>
          <xyz>0 0 -1</xyz>
          <limit>
            <lower>-1.57</lower>
            <upper>0</upper>
            <effort>0.05</effort>
            <velocity>8.73</velocity>
          </limit>
          <dynamics>
            <damping>0</damping>
            <friction>0</friction>
            <spring_reference>0</spring_reference>
            <spring_stiffness>0</spring_stiffness>
          </dynamics>
        </axis>
      </joint>
      <link name='gripper_link_1'>
        <pose relative_to='gripper_joint_1'>0 0 0 0 -0 0</pose>
        <inertial>
          <pose>0.005346 0.039496 0.009482 0 -0 0</pose>
          <mass>0.0096366</mass>
          <inertia>
            <ixx>2.2199e-06</ixx>
            <ixy>-2.3834e-07</ixy>
            <ixz>-1.3995e-11</ixz>
            <iyy>2.2636e-07</iyy>
            <iyz>-1.1442e-12</iyz>
            <izz>2.37e-06</izz>
          </inertia>
        </inertial>
        <collision name='gripper_link_1_collision'>
          <pose>0 0 0 0 -0 0</pose>
          <geometry>
            <mesh>
              <scale>1 1 1</scale>
              <uri>/home/mrinal/ros_ws/catkin_ws/src/mums_assistant/meshes/gripper_link_1.STL</uri>
            </mesh>
          </geometry>
          <surface>
            <contact>
              <ode/>
            </contact>
            <friction>
              <ode/>
              <torsional>
                <ode/>
              </torsional>
            </friction>
            <bounce/>
          </surface>
          <max_contacts>10</max_contacts>
        </collision>
        <visual name='gripper_link_1_visual'>
          <pose>0 0 0 0 -0 0</pose>
          <geometry>
            <mesh>
              <scale>1 1 1</scale>
              <uri>/home/mrinal/ros_ws/catkin_ws/src/mums_assistant/meshes/gripper_link_1.STL</uri>
            </mesh>
          </geometry>
        </visual>
        <self_collide>1</self_collide>
        <enable_wind>0</enable_wind>
        <kinematic>0</kinematic>
      </link>
      <joint name='gripper_joint_2' type='revolute'>
        <pose relative_to='link_5'>0.003343 0.038 0.004999 -1.5707 1.5689 -1.5689</pose>
        <parent>link_5</parent>
        <child>gripper_link_2</child>
        <axis>
          <xyz>0 0 1</xyz>
          <limit>
            <lower>-1.57</lower>
            <upper>0</upper>
            <effort>0.05</effort>
            <velocity>8.73</velocity>
          </limit>
          <dynamics>
            <damping>0</damping>
            <friction>0</friction>
            <spring_reference>0</spring_reference>
            <spring_stiffness>0</spring_stiffness>
          </dynamics>
        </axis>
      </joint>
      <link name='gripper_link_2'>
        <pose relative_to='gripper_joint_2'>0 0 0 0 -0 0</pose>
        <inertial>
          <pose>-0.002488 0.039374 0.009468 0 -0 0</pose>
          <mass>0.0096366</mass>
          <inertia>
            <ixx>2.2128e-06</ixx>
            <ixy>1.8017e-07</ixy>
            <ixz>-1.3983e-11</ixz>
            <iyy>2.3348e-07</iyy>
            <iyz>1.1801e-12</iyz>
            <izz>2.37e-06</izz>
          </inertia>
        </inertial>
        <collision name='gripper_link_2_collision'>
          <pose>0 0 0 0 -0 0</pose>
          <geometry>
            <mesh>
              <scale>1 1 1</scale>
              <uri>/home/mrinal/ros_ws/catkin_ws/src/mums_assistant/meshes/gripper_link_2.STL</uri>
            </mesh>
          </geometry>
          <surface>
            <contact>
              <ode/>
            </contact>
            <friction>
              <ode/>
              <torsional>
                <ode/>
              </torsional>
            </friction>
            <bounce/>
          </surface>
          <max_contacts>10</max_contacts>
        </collision>
        <visual name='gripper_link_2_visual'>
          <pose>0 0 0 0 -0 0</pose>
          <geometry>
            <mesh>
              <scale>1 1 1</scale>
              <uri>/home/mrinal/ros_ws/catkin_ws/src/mums_assistant/meshes/gripper_link_2.STL</uri>
            </mesh>
          </geometry>
        </visual>
        <self_collide>1</self_collide>
        <enable_wind>0</enable_wind>
        <kinematic>0</kinematic>
      </link>
      <plugin name='gazebo_ros_control' filename='libgazebo_ros_control.so'>
        <robotNamespace>/</robotNamespace>
      </plugin>
      <plugin name='joint_state_publisher' filename='libgazebo_ros_joint_state_publisher.so'>
        <jointName>joint_1, joint_2, joint_3, joint_4, joint_5, gripper_joint_1, gripper_joint_2</jointName>
        <robotNamespace>/</robotNamespace>
      </plugin>
      <static>0</static>
      <plugin name='gazebo_grasp_fix' filename='libgazebo_grasp_fix.so'>
        <arm>
          <arm_name>arm</arm_name>
          <palm_link>link_5</palm_link>
          <gripper_link>gripper_link_1</gripper_link>
          <gripper_link>gripper_link_2</gripper_link>
        </arm>
        <forces_angle_tolerance>100</forces_angle_tolerance>
        <update_rate>4</update_rate>
        <grip_count_threshold>4</grip_count_threshold>
        <max_grip_count>8</max_grip_count>
        <release_tolerance>0.005</release_tolerance>
        <disable_collisions_on_attach>0</disable_collisions_on_attach>
        <contact_topic>__default_topic__</contact_topic>
        <robotNamespace>/</robotNamespace>
      </plugin>
      <pose>0 0 0 0 -0 0</pose>
    </model>
    <model name='bowl'>
      <link name='bowl'>
        <collision name='collision_bowl'>
          <geometry>
            <cylinder>
              <radius>0.098</radius>
              <length>0.035</length>
            </cylinder>
          </geometry>
          <max_contacts>10</max_contacts>
          <surface>
            <contact>
              <ode/>
            </contact>
            <bounce/>
            <friction>
              <torsional>
                <ode/>
              </torsional>
              <ode/>
            </friction>
          </surface>
        </collision>
        <visual name='visual_bowl'>
          <geometry>
            <mesh>
              <uri>model://bowl/meshes/model.dae</uri>
              <scale>0.5 0.5 0.5</scale>
            </mesh>
          </geometry>
        </visual>
        <self_collide>0</self_collide>
        <inertial>
          <pose>0 0 0 0 -0 0</pose>
          <inertia>
            <ixx>1</ixx>
            <ixy>0</ixy>
            <ixz>0</ixz>
            <iyy>1</iyy>
            <iyz>0</iyz>
            <izz>1</izz>
          </inertia>
          <mass>1</mass>
        </inertial>
        <enable_wind>0</enable_wind>
        <kinematic>0</kinematic>
      </link>
      <pose>-1.78164 -3.47562 0 0 -0 0</pose>
    </model>
  </world>
</sdf>
