<?xml version="1.0" encoding="utf-8" ?>

<robot name="mums_assistant">
    <link name="base_link">

        <inertial>
            <origin xyz="9.4578E-07 -0.00011719 0.022304" rpy="0 0 0" />
            <!-- <origin xyz="0 0 0" rpy="0 0 0" /> -->
            <mass value="0.096037" />
            <inertia ixx="0.00013766" ixy="7.732E-08" ixz="3.1334E-08" iyy="0.00012799" iyz="-3.9138E-06" izz="0.00020798" />
        </inertial>

        <visual>
            <origin xyz="0 0 0" rpy="0 0 0" />
            <geometry>
                <mesh filename="package://mums_assistant/meshes/base_link.STL" />
            </geometry>
            <material name="">
                <color rgba="0.79216 0.81961 0.93333 1" />
            </material>
        </visual>
        <collision>
            <origin xyz="0 0 0" rpy="0 0 0" />
            <geometry>
                <mesh filename="package://mums_assistant/meshes/base_link.STL" />
            </geometry>
        </collision>
    </link>
    <link name="link_1">

        <inertial>
            <origin xyz="0.001372 0.0092351 0.01597" rpy="0 0 0" />
            <mass value="0.068038" />
            <inertia ixx="4.5018E-05" ixy="-1.6766E-06" ixz="-6.0475E-06" iyy="5.6329E-05" iyz="-5.458E-06" izz="5.648E-05" />
        </inertial>

        <visual>
            <origin xyz="0 0 0" rpy="0 0 0" />
            <geometry>
                <mesh filename="package://mums_assistant/meshes/link_1.STL" />
            </geometry>
            <material name="">
                <color rgba="0.79216 0.81961 0.93333 1" />
            </material>
        </visual>
        <collision>
            <origin xyz="0 0 0" rpy="0 0 0" />
            <geometry>
                <mesh filename="package://mums_assistant/meshes/link_1.STL" />
            </geometry>
        </collision>
    </link>
    <joint name="joint_1" type="revolute">
        <origin xyz="0 0 0.056" rpy="0.16801 0 0" />
        <parent link="base_link" />
        <child link="link_1" />
        <axis xyz="0 0.16722 0.98592" />
        <limit lower="-1.57" upper="1.57" effort="0.92" velocity="6.16" />
        <dynamics damping="0" friction="0" />
    </joint>
    <link name="link_2">

        <inertial>
            <origin xyz="0.00087602 -0.0037688 0.058584" rpy="0 0 0" />
            <mass value="0.064393" />
            <inertia ixx="0.00010701" ixy="-4.3528E-09" ixz="-1.683E-06" iyy="0.00011184" iyz="-2.3957E-07" izz="9.1389E-06" />
        </inertial>

        <visual>
            <origin xyz="0 0 0" rpy="0 0 0" />
            <geometry>
                <mesh filename="package://mums_assistant/meshes/link_2.STL" />
            </geometry>
            <material name="">
                <color rgba="0 0.2549 0.92157 1" />
            </material>
        </visual>
        <collision>
            <origin xyz="0 0 0" rpy="0 0 0" />
            <geometry>
                <mesh filename="package://mums_assistant/meshes/link_2.STL" />
            </geometry>
        </collision>
    </link>
    <joint name="joint_2" type="revolute">
        <origin xyz="0.013919 0.006735 0.039709" rpy="-0.16801 0 0" />
        <parent link="link_1" />
        <child link="link_2" />
        <axis xyz="0 -1 0" />
        <limit lower="-1.57" upper="1.57" effort="0.92" velocity="6.16" />
        <dynamics damping="0" friction="0" />
    </joint>
    <link name="link_3">

        <inertial>
            <origin xyz="0.039285 0.011409 2.7846E-05" rpy="0 0 0" />
            <mass value="0.050268" />
            <inertia ixx="9.2868E-06" ixy="-2.8753E-07" ixz="-6.9585E-08" iyy="5.8149E-05" iyz="-5.4203E-11" izz="5.4601E-05" />
        </inertial>

        <visual>
            <origin xyz="0 0 0" rpy="0 0 0" />
            <geometry>
                <mesh filename="package://mums_assistant/meshes/link_3.STL" />
            </geometry>
            <material name="">
                <color rgba="0.79216 0.81961 0.93333 1" />
            </material>
        </visual>
        <collision>
            <origin xyz="0 0 0" rpy="0 0 0" />
            <geometry>
                <mesh filename="package://mums_assistant/meshes/link_3.STL" />
            </geometry>
        </collision>
    </link>
    <joint name="joint_3" type="revolute">
        <origin xyz="0.0020606 0 0.11998" rpy="0 0.00077559 0" />
        <parent link="link_2" />
        <child link="link_3" />
        <axis xyz="0 1 0" />
        <limit lower="-1.57" upper="1.57" effort="0.92" velocity="6.16" />
        <dynamics damping="0" friction="0" />
    </joint>
    <link name="link_4">

        <inertial>
            <origin xyz="0.017859 -0.0052646 0.0050459" rpy="0 0 0" />
            <mass value="0.016499" />
            <inertia ixx="2.6124E-06" ixy="5.7579E-07" ixz="1.1583E-08" iyy="5.0223E-06" iyz="-3.9825E-09" izz="3.9122E-06" />
        </inertial>

        <visual>
            <origin xyz="0 0 0" rpy="0 0 0" />
            <geometry>
                <mesh filename="package://mums_assistant/meshes/link_4.STL" />
            </geometry>
            <material name="">
                <color rgba="0.79216 0.81961 0.93333 1" />
            </material>
        </visual>
        <collision>
            <origin xyz="0 0 0" rpy="0 0 0" />
            <geometry>
                <mesh filename="package://mums_assistant/meshes/link_4.STL" />
            </geometry>
        </collision>
    </link>
    <joint name="joint_4" type="revolute">
        <origin xyz="0.089732 0.0115 -0.0051" rpy="0.017845 0 0" />
        <parent link="link_3" />
        <child link="link_4" />
        <axis xyz="1 0 0" />
        <limit lower="-1.57" upper="1.57" effort="0.098" velocity="8.73" />
        <dynamics damping="0" friction="0" />
    </joint>
    <link name="link_5">

        <inertial>
            <origin xyz="-0.0058941 -0.012023 0.023532" rpy="0 0 0" />
            <mass value="0.015721" />
            <inertia ixx="8.1067E-06" ixy="3.5504E-07" ixz="1.3823E-06" iyy="7.2474E-06" iyz="-1.4274E-06" izz="2.5695E-06" />
        </inertial>

        <visual>
            <origin xyz="0 0 0" rpy="0 0 0" />
            <geometry>
                <mesh filename="package://mums_assistant/meshes/link_5.STL" />
            </geometry>
            <material name="">
                <color rgba="0.79216 0.81961 0.93333 1" />
            </material>
        </visual>
        <collision>
            <origin xyz="0 0 0" rpy="0 0 0" />
            <geometry>
                <mesh filename="package://mums_assistant/meshes/link_5.STL" />
            </geometry>
        </collision>
    </link>
    <joint name="joint_5" type="revolute">
        <origin xyz="0.028118 0 0.005" rpy="0 0 0" />
        <parent link="link_4" />
        <child link="link_5" />
        <axis xyz="0 1 0" />
        <limit lower="-1.57" upper="1.57" effort="0.098" velocity="8.73" />
        <dynamics damping="0" friction="0" />
    </joint>
    <link name="gripper_link_1">

        <inertial>
            <origin xyz="-0.0061409 0.0039809 0.038541" rpy="0 0 0" />
            <mass value="0.0079633" />
            <inertia ixx="2.1601E-06" ixy="-1.4003E-11" ixz="5.0583E-13" iyy="1.9347E-06" iyz="2.0596E-07" izz="2.9726E-07" />
        </inertial>

        <visual>
            <origin xyz="0 0 0" rpy="0 0 0" />
            <geometry>
                <mesh filename="package://mums_assistant/meshes/gripper_link_1.STL" />
            </geometry>
            <material name="">
                <color rgba="0.79216 0.81961 0.93333 1" />
            </material>
        </visual>
        <collision>
            <origin xyz="0 0 0" rpy="0 0 0" />
            <geometry>
                <mesh filename="package://mums_assistant/meshes/gripper_link_1.STL" />
            </geometry>
        </collision>
    </link>
    <joint name="gripper_joint_1" type="revolute">
        <origin xyz="-0.0057476 0.004 0.037981" rpy="0 -0.0032835 0" />
        <parent link="link_5" />
        <child link="gripper_link_1" />
        <axis xyz="-1 0 0" />
        <limit lower="-1.57" upper="1.57" effort="0.05" velocity="8.73" />
        <dynamics damping="0" friction="0" />
    </joint>
    <link name="gripper_link_2">

        <inertial>
            <origin xyz="-0.006061 0.0040629 0.039426" rpy="0 0 0" />
            <mass value="0.0080391" />
            <inertia ixx="2.1612E-06" ixy="-1.3965E-11" ixz="7.2299E-13" iyy="1.9156E-06" iyz="-3.9649E-07" izz="3.1758E-07" />
        </inertial>

        <visual>
            <origin xyz="0 0 0" rpy="0 0 0" />
            <geometry>
                <mesh filename="package://mums_assistant/meshes/gripper_link_2.STL" />
            </geometry>
            <material name="">
                <color rgba="0.79216 0.81961 0.93333 1" />
            </material>
        </visual>
        <collision>
            <origin xyz="0 0 0" rpy="0 0 0" />
            <geometry>
                <mesh filename="package://mums_assistant/meshes/gripper_link_2.STL" />
            </geometry>
        </collision>
    </link>
    <joint name="gripper_joint_2" type="revolute">
        <origin xyz="-0.0058674 -0.023 0.037981" rpy="0 -0.0032835 0" />
        <parent link="link_5" />
        <child link="gripper_link_2" />
        <axis xyz="-1 0 0" />
        <limit lower="-1.57" upper="1.57" effort="0.05" velocity="8.73" />
        <dynamics damping="0" friction="0" />
        <mimic joint="gripper_joint_1" multiplier="-1" offset="0" />
    </joint>

<transmission name="trans_joint_1">
        <type>transmission_interface/SimpleTransmission</type>
        <joint name="joint_1">
            <hardwareInterface>hardware_interface/EffortJointInterface</hardwareInterface>
        </joint>
        <actuator name="joint_1_motor">
            <hardwareInterface>hardware_interface/EffortJointInterface</hardwareInterface>
            <mechanicalReduction>1</mechanicalReduction>
        </actuator>
    </transmission>
    <transmission name="trans_joint_2">
        <type>transmission_interface/SimpleTransmission</type>
        <joint name="joint_2">
            <hardwareInterface>hardware_interface/EffortJointInterface</hardwareInterface>
        </joint>
        <actuator name="joint_2_motor">
            <hardwareInterface>hardware_interface/EffortJointInterface</hardwareInterface>
            <mechanicalReduction>1</mechanicalReduction>
        </actuator>
    </transmission>
    <transmission name="trans_joint_3">
        <type>transmission_interface/SimpleTransmission</type>
        <joint name="joint_3">
            <hardwareInterface>hardware_interface/EffortJointInterface</hardwareInterface>
        </joint>
        <actuator name="joint_3_motor">
            <hardwareInterface>hardware_interface/EffortJointInterface</hardwareInterface>
            <mechanicalReduction>1</mechanicalReduction>
        </actuator>
    </transmission>
    <transmission name="trans_joint_4">
        <type>transmission_interface/SimpleTransmission</type>
        <joint name="joint_4">
            <hardwareInterface>hardware_interface/EffortJointInterface</hardwareInterface>
        </joint>
        <actuator name="joint_4_motor">
            <hardwareInterface>hardware_interface/EffortJointInterface</hardwareInterface>
            <mechanicalReduction>1</mechanicalReduction>
        </actuator>
    </transmission>
    <transmission name="trans_joint_5">
        <type>transmission_interface/SimpleTransmission</type>
        <joint name="joint_5">
            <hardwareInterface>hardware_interface/EffortJointInterface</hardwareInterface>
        </joint>
        <actuator name="joint_5_motor">
            <hardwareInterface>hardware_interface/EffortJointInterface</hardwareInterface>
            <mechanicalReduction>1</mechanicalReduction>
        </actuator>
    </transmission>
    <transmission name="trans_gripper_joint_1">
        <type>transmission_interface/SimpleTransmission</type>
        <joint name="gripper_joint_1">
            <hardwareInterface>hardware_interface/EffortJointInterface</hardwareInterface>
        </joint>
        <actuator name="gripper_joint_1_motor">
            <hardwareInterface>hardware_interface/EffortJointInterface</hardwareInterface>
            <mechanicalReduction>1</mechanicalReduction>
        </actuator>
    </transmission>
    <transmission name="trans_gripper_joint_2">
        <type>transmission_interface/SimpleTransmission</type>
        <joint name="gripper_joint_2">
            <hardwareInterface>hardware_interface/EffortJointInterface</hardwareInterface>
        </joint>
        <actuator name="gripper_joint_2_motor">
            <hardwareInterface>hardware_interface/EffortJointInterface</hardwareInterface>
            <mechanicalReduction>1</mechanicalReduction>
        </actuator>
    </transmission>
    <gazebo>
        <plugin name="gazebo_ros_control" filename="libgazebo_ros_control.so" />
    </gazebo>
    <transmission name="trans_joint_1">
        <type>transmission_interface/SimpleTransmission</type>
        <joint name="joint_1">
            <hardwareInterface>hardware_interface/EffortJointInterface</hardwareInterface>
        </joint>
        <actuator name="joint_1_motor">
            <hardwareInterface>hardware_interface/EffortJointInterface</hardwareInterface>
            <mechanicalReduction>1</mechanicalReduction>
        </actuator>
    </transmission>
    <transmission name="trans_joint_2">
        <type>transmission_interface/SimpleTransmission</type>
        <joint name="joint_2">
            <hardwareInterface>hardware_interface/EffortJointInterface</hardwareInterface>
        </joint>
        <actuator name="joint_2_motor">
            <hardwareInterface>hardware_interface/EffortJointInterface</hardwareInterface>
            <mechanicalReduction>1</mechanicalReduction>
        </actuator>
    </transmission>
    <transmission name="trans_joint_3">
        <type>transmission_interface/SimpleTransmission</type>
        <joint name="joint_3">
            <hardwareInterface>hardware_interface/EffortJointInterface</hardwareInterface>
        </joint>
        <actuator name="joint_3_motor">
            <hardwareInterface>hardware_interface/EffortJointInterface</hardwareInterface>
            <mechanicalReduction>1</mechanicalReduction>
        </actuator>
    </transmission>
    <transmission name="trans_joint_4">
        <type>transmission_interface/SimpleTransmission</type>
        <joint name="joint_4">
            <hardwareInterface>hardware_interface/EffortJointInterface</hardwareInterface>
        </joint>
        <actuator name="joint_4_motor">
            <hardwareInterface>hardware_interface/EffortJointInterface</hardwareInterface>
            <mechanicalReduction>1</mechanicalReduction>
        </actuator>
    </transmission>
    <transmission name="trans_joint_5">
        <type>transmission_interface/SimpleTransmission</type>
        <joint name="joint_5">
            <hardwareInterface>hardware_interface/EffortJointInterface</hardwareInterface>
        </joint>
        <actuator name="joint_5_motor">
            <hardwareInterface>hardware_interface/EffortJointInterface</hardwareInterface>
            <mechanicalReduction>1</mechanicalReduction>
        </actuator>
    </transmission>
    <transmission name="trans_gripper_joint_1">
        <type>transmission_interface/SimpleTransmission</type>
        <joint name="gripper_joint_1">
            <hardwareInterface>hardware_interface/EffortJointInterface</hardwareInterface>
        </joint>
        <actuator name="gripper_joint_1_motor">
            <hardwareInterface>hardware_interface/EffortJointInterface</hardwareInterface>
            <mechanicalReduction>1</mechanicalReduction>
        </actuator>
    </transmission>
    <transmission name="trans_gripper_joint_2">
        <type>transmission_interface/SimpleTransmission</type>
        <joint name="gripper_joint_2">
            <hardwareInterface>hardware_interface/EffortJointInterface</hardwareInterface>
        </joint>
        <actuator name="gripper_joint_2_motor">
            <hardwareInterface>hardware_interface/EffortJointInterface</hardwareInterface>
            <mechanicalReduction>1</mechanicalReduction>
        </actuator>
    </transmission>
    <gazebo>
        <plugin name="gazebo_ros_control" filename="libgazebo_ros_control.so" />
    </gazebo>
    <transmission name="trans_joint_1">
        <type>transmission_interface/SimpleTransmission</type>
        <joint name="joint_1">
            <hardwareInterface>hardware_interface/PositionJointInterface</hardwareInterface>
        </joint>
        <actuator name="joint_1_motor">
            <hardwareInterface>hardware_interface/PositionJointInterface</hardwareInterface>
            <mechanicalReduction>1</mechanicalReduction>
        </actuator>
    </transmission>
    <transmission name="trans_joint_2">
        <type>transmission_interface/SimpleTransmission</type>
        <joint name="joint_2">
            <hardwareInterface>hardware_interface/PositionJointInterface</hardwareInterface>
        </joint>
        <actuator name="joint_2_motor">
            <hardwareInterface>hardware_interface/PositionJointInterface</hardwareInterface>
            <mechanicalReduction>1</mechanicalReduction>
        </actuator>
    </transmission>
    <transmission name="trans_joint_3">
        <type>transmission_interface/SimpleTransmission</type>
        <joint name="joint_3">
            <hardwareInterface>hardware_interface/PositionJointInterface</hardwareInterface>
        </joint>
        <actuator name="joint_3_motor">
            <hardwareInterface>hardware_interface/PositionJointInterface</hardwareInterface>
            <mechanicalReduction>1</mechanicalReduction>
        </actuator>
    </transmission>
    <transmission name="trans_joint_4">
        <type>transmission_interface/SimpleTransmission</type>
        <joint name="joint_4">
            <hardwareInterface>hardware_interface/PositionJointInterface</hardwareInterface>
        </joint>
        <actuator name="joint_4_motor">
            <hardwareInterface>hardware_interface/PositionJointInterface</hardwareInterface>
            <mechanicalReduction>1</mechanicalReduction>
        </actuator>
    </transmission>
    <transmission name="trans_joint_5">
        <type>transmission_interface/SimpleTransmission</type>
        <joint name="joint_5">
            <hardwareInterface>hardware_interface/PositionJointInterface</hardwareInterface>
        </joint>
        <actuator name="joint_5_motor">
            <hardwareInterface>hardware_interface/PositionJointInterface</hardwareInterface>
            <mechanicalReduction>1</mechanicalReduction>
        </actuator>
    </transmission>
    <transmission name="trans_gripper_joint_1">
        <type>transmission_interface/SimpleTransmission</type>
        <joint name="gripper_joint_1">
            <hardwareInterface>hardware_interface/EffortJointInterface</hardwareInterface>
        </joint>
        <actuator name="gripper_joint_1_motor">
            <hardwareInterface>hardware_interface/EffortJointInterface</hardwareInterface>
            <mechanicalReduction>1</mechanicalReduction>
        </actuator>
    </transmission>
    <transmission name="trans_gripper_joint_2">
        <type>transmission_interface/SimpleTransmission</type>
        <joint name="gripper_joint_2">
            <hardwareInterface>hardware_interface/EffortJointInterface</hardwareInterface>
        </joint>
        <actuator name="gripper_joint_2_motor">
            <hardwareInterface>hardware_interface/EffortJointInterface</hardwareInterface>
            <mechanicalReduction>1</mechanicalReduction>
        </actuator>
    </transmission>
    <gazebo>
        <plugin name="gazebo_ros_control" filename="libgazebo_ros_control.so">
        </plugin>
    </gazebo>
    <gazebo>
        <plugin name="joint_state_publisher" filename="libgazebo_ros_joint_state_publisher.so">
            <jointName>joint_1, joint_2, joint_3, joint_4, joint_5</jointName>
        </plugin>
    </gazebo>

    <gazebo reference="link_1">
        <selfCollide>true</selfCollide>
    </gazebo>
    <gazebo reference="link_2">
        <selfCollide>true</selfCollide>
    </gazebo>
    <gazebo reference="link_3">
        <selfCollide>true</selfCollide>
    </gazebo>
    <gazebo reference="link_4">
        <selfCollide>true</selfCollide>
    </gazebo>
    <gazebo reference="link_5">
        <selfCollide>true</selfCollide>
    </gazebo>
    <gazebo reference="gripper_link_1">
        <selfCollide>true</selfCollide>
    </gazebo>

</robot>

<!-- FOLLOW EYRC WALA -->